Error coming from auto assignment:

Traceback (most recent call last):
  File "/Library/Python/3.7/site-packages/urllib3/connection.py", line 157, in _new_conn
    (self._dns_host, self.port), self.timeout, **extra_kw
  File "/Library/Python/3.7/site-packages/urllib3/util/connection.py", line 84, in create_connection
    raise err
  File "/Library/Python/3.7/site-packages/urllib3/util/connection.py", line 74, in create_connection
    sock.connect(sa)
OSError: [Errno 50] Network is down

During handling of the above exception, another exception occurred:

Traceback (most recent call last):
  File "/Library/Python/3.7/site-packages/urllib3/connectionpool.py", line 672, in urlopen
    chunked=chunked,
  File "/Library/Python/3.7/site-packages/urllib3/connectionpool.py", line 376, in _make_request
    self._validate_conn(conn)
  File "/Library/Python/3.7/site-packages/urllib3/connectionpool.py", line 994, in _validate_conn
    conn.connect()
  File "/Library/Python/3.7/site-packages/urllib3/connection.py", line 334, in connect
    conn = self._new_conn()
  File "/Library/Python/3.7/site-packages/urllib3/connection.py", line 169, in _new_conn
    self, "Failed to establish a new connection: %s" % e
urllib3.exceptions.NewConnectionError: <urllib3.connection.VerifiedHTTPSConnection object at 0x10eb05978>: Failed to establish a new connection: [Errno 50] Network is down

During handling of the above exception, another exception occurred:

Traceback (most recent call last):
  File "/Library/Python/3.7/site-packages/requests/adapters.py", line 449, in send
    timeout=timeout
  File "/Library/Python/3.7/site-packages/urllib3/connectionpool.py", line 720, in urlopen
    method, url, error=e, _pool=self, _stacktrace=sys.exc_info()[2]
  File "/Library/Python/3.7/site-packages/urllib3/util/retry.py", line 436, in increment
    raise MaxRetryError(_pool, url, error or ResponseError(cause))
urllib3.exceptions.MaxRetryError: HTTPSConnectionPool(host='contentful.zendesk.com', port=443): Max retries exceeded with url: /api/v2/search.json?query=type:ticket%20status%3C=pending%20assignee:none%20group:20917813 (Caused by NewConnectionError('<urllib3.connection.VerifiedHTTPSConnection object at 0x10eb05978>: Failed to establish a new connection: [Errno 50] Network is down'))

During handling of the above exception, another exception occurred:

Traceback (most recent call last):
  File "autoassignmenttestrun.py", line 178, in <module>
    main()
  File "autoassignmenttestrun.py", line 128, in main
    getUnassignedTickets()
  File "autoassignmenttestrun.py", line 40, in getUnassignedTickets
    unassignedTicketsSupportresponse = requests.get(basic_url+unassignedTicketsQuery+group_id_support,headers=headers)
  File "/Library/Python/3.7/site-packages/requests/api.py", line 75, in get
    return request('get', url, params=params, **kwargs)
  File "/Library/Python/3.7/site-packages/requests/api.py", line 60, in request
    return session.request(method=method, url=url, **kwargs)
  File "/Library/Python/3.7/site-packages/requests/sessions.py", line 533, in request
    resp = self.send(prep, **send_kwargs)
  File "/Library/Python/3.7/site-packages/requests/sessions.py", line 646, in send
    r = adapter.send(request, **kwargs)
  File "/Library/Python/3.7/site-packages/requests/adapters.py", line 516, in send
    raise ConnectionError(e, request=request)
requests.exceptions.ConnectionError: HTTPSConnectionPool(host='contentful.zendesk.com', port=443): Max retries exceeded with url: /api/v2/search.json?query=type:ticket%20status%3C=pending%20assignee:none%20group:20917813 (Caused by NewConnectionError('<urllib3.connection.VerifiedHTTPSConnection object at 0x10eb05978>: Failed to establish a new connection: [Errno 50] Network is down'))